<sdf version='1.7'>
  <model name='drone_ros_sim_urdf'>
    <link name='frame'>
      <inertial>
        <pose>-0.000335 -8.2e-05 0.46442 0 -0 0</pose>
        <mass>7.9807</mass>
        <inertia>
          <ixx>0.033649</ixx>
          <ixy>1.2106e-06</ixy>
          <ixz>-2.0293e-06</ixz>
          <iyy>0.029642</iyy>
          <iyz>-1.0527e-07</iyz>
          <izz>0.046218</izz>
        </inertia>
      </inertial>
      <collision name='frame_collision'>
        <pose>0 0 0 0 -0 0</pose>
        <geometry>
          <mesh>
            <scale>1 1 1</scale>
            <uri>model://drone_ros_sim_urdf/meshes/frame.STL</uri>
          </mesh>
        </geometry>
      </collision>
      <visual name='frame_visual'>
        <pose>0 0 0 0 -0 0</pose>
        <geometry>
          <mesh>
            <scale>1 1 1</scale>
            <uri>model://drone_ros_sim_urdf/meshes/frame.STL</uri>
          </mesh>
        </geometry>
      </visual>
    </link>
    <joint name='joint1' type='revolute'>
      <pose relative_to='frame'>0 0 0 0 -0 0</pose>
      <parent>frame</parent>
      <child>prop1_ccw</child>
      <axis>
        <xyz>0 0 1</xyz>
        <limit>
          <effort>9.55</effort>
          <velocity>10.472</velocity>
          <lower>-1e+16</lower>
          <upper>1e+16</upper>
        </limit>
        <dynamics>
          <spring_reference>0</spring_reference>
          <spring_stiffness>0</spring_stiffness>
        </dynamics>
      </axis>
    </joint>
    <link name='prop1_ccw'>
      <pose relative_to='joint1'>0 0 0 0 -0 0</pose>
      <inertial>
        <pose>0.45342 0.45343 0.54325 0 -0 0</pose>
        <mass>0.10735</mass>
        <inertia>
          <ixx>0.00027815</ixx>
          <ixy>0.00028006</ixy>
          <ixz>1.0025e-08</ixz>
          <iyy>0.00030502</iyy>
          <iyz>-8.1576e-09</iyz>
          <izz>0.00058081</izz>
        </inertia>
      </inertial>
      <collision name='prop1_ccw_collision'>
        <pose>0 0 0 0 -0 0</pose>
        <geometry>
          <mesh>
            <scale>1 1 1</scale>
            <uri>model://drone_ros_sim_urdf/meshes/prop1_ccw.STL</uri>
          </mesh>
        </geometry>
      </collision>
      <visual name='prop1_ccw_visual'>
        <pose>0 0 0 0 -0 0</pose>
        <geometry>
          <mesh>
            <scale>1 1 1</scale>
            <uri>model://drone_ros_sim_urdf/meshes/prop1_ccw.STL</uri>
          </mesh>
        </geometry>
      </visual>
    </link>
    <joint name='joint2' type='revolute'>
      <pose relative_to='frame'>0 0 0 0 -0 0</pose>
      <parent>frame</parent>
      <child>prop2_ccw</child>
      <axis>
        <xyz>0 0 1</xyz>
        <limit>
          <effort>9.55</effort>
          <velocity>10.472</velocity>
          <lower>-1e+16</lower>
          <upper>1e+16</upper>
        </limit>
        <dynamics>
          <spring_reference>0</spring_reference>
          <spring_stiffness>0</spring_stiffness>
        </dynamics>
      </axis>
    </joint>
    <link name='prop2_ccw'>
      <pose relative_to='joint2'>0 0 0 0 -0 0</pose>
      <inertial>
        <pose>-0.45273 -0.45272 0.54325 0 -0 0</pose>
        <mass>0.10735</mass>
        <inertia>
          <ixx>0.00027815</ixx>
          <ixy>0.00028006</ixy>
          <ixz>1.0025e-08</ixz>
          <iyy>0.00030502</iyy>
          <iyz>-8.158e-09</iyz>
          <izz>0.00058081</izz>
        </inertia>
      </inertial>
      <collision name='prop2_ccw_collision'>
        <pose>0 0 0 0 -0 0</pose>
        <geometry>
          <mesh>
            <scale>1 1 1</scale>
            <uri>model://drone_ros_sim_urdf/meshes/prop2_ccw.STL</uri>
          </mesh>
        </geometry>
      </collision>
      <visual name='prop2_ccw_visual'>
        <pose>0 0 0 0 -0 0</pose>
        <geometry>
          <mesh>
            <scale>1 1 1</scale>
            <uri>model://drone_ros_sim_urdf/meshes/prop2_ccw.STL</uri>
          </mesh>
        </geometry>
      </visual>
    </link>
    <joint name='joint3' type='revolute'>
      <pose relative_to='frame'>0 0 0 0 -0 0</pose>
      <parent>frame</parent>
      <child>prop3_cw</child>
      <axis>
        <xyz>0 0 1</xyz>
        <limit>
          <effort>9.55</effort>
          <velocity>10.472</velocity>
          <lower>-1e+16</lower>
          <upper>1e+16</upper>
        </limit>
        <dynamics>
          <spring_reference>0</spring_reference>
          <spring_stiffness>0</spring_stiffness>
        </dynamics>
      </axis>
    </joint>
    <link name='prop3_cw'>
      <pose relative_to='joint3'>0 0 0 0 -0 0</pose>
      <inertial>
        <pose>-0.45342 0.45343 0.54325 0 -0 0</pose>
        <mass>0.10734</mass>
        <inertia>
          <ixx>0.00027811</ixx>
          <ixy>-0.00028002</ixy>
          <ixz>-1.0035e-08</ixz>
          <iyy>0.00030496</iyy>
          <iyz>-8.1513e-09</iyz>
          <izz>0.00058072</izz>
        </inertia>
      </inertial>
      <collision name='prop3_cw_collision'>
        <pose>0 0 0 0 -0 0</pose>
        <geometry>
          <mesh>
            <scale>1 1 1</scale>
            <uri>model://drone_ros_sim_urdf/meshes/prop3_cw.STL</uri>
          </mesh>
        </geometry>
      </collision>
      <visual name='prop3_cw_visual'>
        <pose>0 0 0 0 -0 0</pose>
        <geometry>
          <mesh>
            <scale>1 1 1</scale>
            <uri>model://drone_ros_sim_urdf/meshes/prop3_cw.STL</uri>
          </mesh>
        </geometry>
      </visual>
    </link>
    <joint name='joint4' type='revolute'>
      <pose relative_to='frame'>0 0 0 0 -0 0</pose>
      <parent>frame</parent>
      <child>prop4_cw</child>
      <axis>
        <xyz>0 0 1</xyz>
        <limit>
          <effort>9.55</effort>
          <velocity>10.472</velocity>
          <lower>-1e+16</lower>
          <upper>1e+16</upper>
        </limit>
        <dynamics>
          <spring_reference>0</spring_reference>
          <spring_stiffness>0</spring_stiffness>
        </dynamics>
      </axis>
    </joint>
    <link name='prop4_cw'>
      <pose relative_to='joint4'>0 0 0 0 -0 0</pose>
      <inertial>
        <pose>0.45273 -0.45272 0.54325 0 -0 0</pose>
        <mass>0.10734</mass>
        <inertia>
          <ixx>0.00027813</ixx>
          <ixy>-0.00028003</ixy>
          <ixz>-1.0044e-08</ixz>
          <iyy>0.00030498</iyy>
          <iyz>-8.1591e-09</iyz>
          <izz>0.00058075</izz>
        </inertia>
      </inertial>
      <collision name='prop4_cw_collision'>
        <pose>0 0 0 0 -0 0</pose>
        <geometry>
          <mesh>
            <scale>1 1 1</scale>
            <uri>model://drone_ros_sim_urdf/meshes/prop4_cw.STL</uri>
          </mesh>
        </geometry>
      </collision>
      <visual name='prop4_cw_visual'>
        <pose>0 0 0 0 -0 0</pose>
        <geometry>
          <mesh>
            <scale>1 1 1</scale>
            <uri>model://drone_ros_sim_urdf/meshes/prop4_cw.STL</uri>
          </mesh>
        </geometry>
      </visual>
    </link>
  </model>
</sdf>
